<?xml version="1.0" ?>
<sdf version="1.5">
  <model name="two_wheeled_robot">  
  <static>false</static>
	
  <!-- ****************** ROBOT BASE FOOTPRINT ***************************  -->
  <pose>0.0 0.0 0.0 0.0 0.0 0.0</pose>
  <link name="base_footprint"/>

  <!-- ********************** ROBOT BASE *********************************  -->
  <link name="base_link">

    <collision name="base_collision">
      <pose>0 0 0.1 0 0 0</pose>
      <geometry>
        <box>
          <size>0.30 0.34 0.02</size>
        </box>
      </geometry>
     
    </collision>

    <visual name="base_visual">
      <pose>0 0 -0.05 0 0 0</pose>
      <geometry>
        <box>
          <size>0.30 0.34 0.02</size>
        </box>
      </geometry>
      <!--
      <geometry>
        <mesh>
          <uri>model://two_wheeled_robot_description/meshes/robot_base.stl</uri>
          <scale>1.0 1.0 1.0</scale>
        </mesh>
      </geometry>
      -->
      <material>
        <ambient>1.0 0.0 0.0 1.0</ambient>
        <diffuse>1.0 0.0 0.0 1.0</diffuse>
        <specular>0.0 0.0 0.0 1.0</specular>
        <emissive>0.0 0.0 0.0 1.0</emissive>
      </material>
    </visual>
     <inertial>
     		 <ixx>0.004878</ixx>
				  <ixy>0</ixy>
				  <ixz>0</ixz>
				  <iyy>0.00090164</iyy>
				  <iyz>-0.00014394</iyz>
				  <izz>0.0042946</izz>
      	<mass>10</mass>
      </inertial>
  </link>
  
  <link name="left_front_lower_pillar">
  	<visual name="visual">
      <pose>0.14 .16 -0.01 0 0 0</pose>
      <geometry>
        <box>
          <size>0.02 0.02 0.06</size>
        </box>
      </geometry>
     </visual>
  </link>
  
  <link name="right_front_lower_pillar">
  	<visual name="visual">
      <pose>0.14 -0.16 -0.01 0 0 0</pose>
      <geometry>
        <box>
          <size>0.02 0.02 0.06</size>
        </box>
      </geometry>
     </visual>
  </link>
  
  <link name="right_rear_lower_pillar">
  	<visual name="visual">
      <pose>-0.14 -0.16 -0.01 0 0 0</pose>
      <geometry>
        <box>
          <size>0.02 0.02 0.06</size>
        </box>
      </geometry>
     </visual>
  </link>
  <link name="left_rear_lower_pillar">
  	<visual name="visual">
      <pose>-0.14 0.16 -0.01 0 0 0</pose>
      <geometry>
        <box>
          <size>0.02 0.02 0.06</size>
        </box>
      </geometry>
     </visual>
  </link>
  <link name="mid_platform">
			<visual name="mid_visual">
		    <pose>0 0 0.03 1.5707963267949 0 3.141592654</pose>
		    <geometry>
		      <box>
		        <size>0.30 0.02 0.34</size>
		      </box>
		    </geometry>
		  </visual>
		  <collision name="collision">
		    <pose>0 0 0.03 1.5707963267949 0 3.141592654</pose>
		    <geometry>
		      <box>
		        <size>0.30 0.02 0.34</size>
		      </box>
		    </geometry>
		  </collision>
		  <inertial>
     		 <ixx>0.004878</ixx>
				  <ixy>0</ixy>
				  <ixz>0</ixz>
				  <iyy>0.00090164</iyy>
				  <iyz>-0.00014394</iyz>
				  <izz>0.0042946</izz>
      	<mass>10</mass>
      </inertial>
   </link>
   <link name="sensor_tower">
			<visual name="visual">
		    <pose>0.06 0 0.08 0 0 0</pose>
		    <geometry>
		      <box>
		        <size>0.14 0.14 0.1</size>
		      </box>
		    </geometry>
		  </visual>
		  <collision name="collision">
		    <pose>0.06 0 0.08 0 0 0</pose>
		    <geometry>
		      <box>
		        <size>0.14 0.14 0.1</size>
		      </box>
		    </geometry>
		  </collision>
		  <inertial>
     		  <ixx>0.004878</ixx>
				  <ixy>0</ixy>
				  <ixz>0</ixz>
				  <iyy>0.00090164</iyy>
				  <iyz>-0.00014394</iyz>
				  <izz>0.000006</izz>
      	<mass>1</mass>
      </inertial>
   </link>
  <!-- *********************** CAMERA ********************************** -->
  <link name="camera_link">

 		<visual name="camera_visual">
 			<pose>0.15 0 0.12 0 0 0</pose>
      <geometry>
    		<box>
    			<size>0.02 0.04 0.02</size>
    		</box>
      </geometry>
    </visual>
		<collision name="camera_collision">
		  <pose>0.15 0 0.12 0 0 0</pose>
		  <geometry>
    		<box>
    			<size>0.02 0.04 0.02</size>
    		</box>
      </geometry>
		</collision>
    <sensor name='camera1' type='camera'>
    	<pose>0.15 0 0.12 0 0 0</pose>
				<camera name="head">
					<horizontal_fov>1.3962634</horizontal_fov>
					<image>
					  <width>640</width>
					  <height>480</height>
					  <format>R8G8B8</format>
					</image>
					<clip>
					  <near>0.1</near>
					  <far>300</far>
					</clip>
				</camera>
				<update_rate>30</update_rate>
				<visualize>1</visualize>
				<plugin name="camera_controller" filename="libgazebo_ros_camera.so">
					<always_on>true</always_on>
					<camera_name>main_camera</camera_name>
					<imageTopicName>image_raw</imageTopicName>
					<cameraInfoTopicName>camera_info</cameraInfoTopicName>
					<frame_name>camera_link</frame_name>
			</plugin>	
		</sensor>
  </link>
  

  <!-- *********************** IMU SENSOR SETUP **************************  -->
  <link name="imu_link">
    <gravity>true</gravity>
    <sensor name="bmb_imu" type="imu">
      <always_on>true</always_on>
      <update_rate>100</update_rate>
      <visualize>true</visualize>
      <imu>
        <orientation>
          <x>
            <noise type="gaussian">
              <mean>0.0</mean>
              <stddev>2e-3</stddev>
            </noise>
          </x>
          <y>
            <noise type="gaussian">
              <mean>0.0</mean>
              <stddev>2e-3</stddev>
            </noise>
          </y>
          <z>
            <noise type="gaussian">
              <mean>0.0</mean>
              <stddev>2e-3</stddev>
            </noise>
          </z>
        </orientation>
        <angular_velocity>
          <x>
            <noise type="gaussian">
              <mean>0.0</mean>
              <stddev>2e-4</stddev>
            </noise>
          </x>
          <y>
            <noise type="gaussian">
              <mean>0.0</mean>
              <stddev>2e-4</stddev>
            </noise>
          </y>
          <z>
            <noise type="gaussian">
              <mean>0.0</mean>
              <stddev>2e-4</stddev>
            </noise>
          </z>
        </angular_velocity>
        <linear_acceleration>
          <x>
            <noise type="gaussian">
              <mean>0.0</mean>
              <stddev>1.7e-2</stddev>
            </noise>
          </x>
          <y>
            <noise type="gaussian">
              <mean>0.0</mean>
              <stddev>1.7e-2</stddev>
            </noise>
          </y>
          <z>
            <noise type="gaussian">
              <mean>0.0</mean>
              <stddev>1.7e-2</stddev>
            </noise>
          </z>
        </linear_acceleration>
      </imu>
      <plugin name="basic_mobile_bot_imu" filename="libgazebo_ros_imu_sensor.so">
        <initial_orientation_as_reference>false</initial_orientation_as_reference>
        <frame_name>imu_link</frame_name>
        <ros>
          <namespace>/imu</namespace>
          <remapping>~/out:=data</remapping>
        </ros>
      </plugin>
    </sensor>
  </link>

  <!-- *********************** GPS SETUP *********************************  -->
  <link name="gps_link">
    <sensor name="bmb_gps" type="gps">
      <always_on>true</always_on>
      <update_rate>10.0</update_rate>
      <gps>
        <position_sensing>
          <horizontal>
            <noise type="gaussian">
              <mean>0.0</mean>
              <stddev>1e-2</stddev>
            </noise>
          </horizontal>
          <vertical>
            <noise type="gaussian">
              <mean>0.0</mean>
              <stddev>1</stddev>
            </noise>
          </vertical>
        </position_sensing>
      </gps>
      <plugin name="basic_mobile_bot_gps" filename="libgazebo_ros_gps_sensor.so">
        <ros>
          <remapping>~/out:=gps/fix</remapping>
        </ros>
      </plugin>
    </sensor>
  </link>

  <!-- *********************** DRIVE WHEELS ******************************  -->
  <link name="drivewhl_l_link">
    <pose>0.10 0.2 -0.07 0 1.570796 1.570796</pose>
    
    <collision name="drivewhl_l_collision">
      <geometry>
        <cylinder>
          <radius>0.045</radius>
          <length>0.015</length>
        </cylinder>
      </geometry>
    </collision>

    <visual name="drivewhl_l_visual">
      <geometry>
        <cylinder>
          <radius>0.045</radius>
          <length>0.015</length>
        </cylinder>
      </geometry>
    </visual>
  </link>

  <link name="drivewhl_r_link">
    <pose>0.10 -0.2 -0.07 0 1.570796 1.570796</pose>
    
    <collision name="drivewhl_r_collision">
      <geometry>
        <cylinder>
          <radius>0.045</radius>
          <length>0.015</length>
        </cylinder>
      </geometry>
    </collision>

    <visual name="drivewhl_r_visual">
      <geometry>
        <cylinder>
          <radius>0.045</radius>
          <length>0.015</length>
        </cylinder>
      </geometry>
    </visual>
  </link>

  <!-- *********************** CASTER WHEELS ******************************  -->

  
  <link name='rear_caster_l'>
    <pose>-0.135 0.16 -0.08 0 0 0</pose>
    <collision name='collision'>
      <geometry>
            <sphere>
                <radius>0.035</radius>
            </sphere>
        </geometry>
      <surface>
            <friction>
                <ode>
                    <mu>0.000008</mu>
                    <mu2>0.000008</mu2>
                    <slip1>0.0</slip1>
                    <slip2>0.0</slip2>
                </ode>
            </friction>
        </surface>
    </collision>
    <visual name="rear_caster_visual_r">
      <geometry>
            <sphere>
                <radius>0.035</radius>
            </sphere>
        </geometry>
    </visual>
    <inertial>
          <origin xyz="0 0 0" rpy="0 0 0"/>
          <mass value="0.25"/>
          <inertia ixx="0.1" ixy="0.0" ixz="0.0" iyy="0.1"  iyz="0.0" izz="0.1"/>
      </inertial>
  </link>
  
  <link name='rear_caster_r'>
    <pose>-0.135 -0.16 -0.08 0 0 0</pose>
    <collision name='collision'>
      <geometry>
            <sphere>
                <radius>0.035</radius>
            </sphere>
        </geometry>
      	<surface>
            <friction>
                <ode>
                    <mu>0.000008</mu>
                    <mu2>0.000008</mu2>
                    <slip1>0.0</slip1>
                    <slip2>0.0</slip2>
                </ode>
            </friction>
        </surface>
    </collision>
    <visual name="rear_caster_visual_r">
      <geometry>
            <sphere>
                <radius>0.035</radius>
            </sphere>
        </geometry>
    </visual>
  </link>
  
  <!-- ****************************** LIDAR *****************************    -->
	<link name="lidar_link">    
		<inertial>
		  <pose>0.06 0 0.15 0 0 0</pose>
		  <inertia>
		    <ixx>0.001</ixx>
		    <ixy>0.000</ixy>
		    <ixz>0.000</ixz>
		    <iyy>0.001</iyy>
		    <iyz>0.000</iyz>
		    <izz>0.001</izz>
		  </inertia>
		  <mass>0.114</mass>
		</inertial>
	 
		<collision name="lidar_collision">
		  <pose>0.06 0 0.15 0 0 0</pose>
		  <geometry>
		    <cylinder>
		      <radius>0.02</radius>
		      <length>0.04</length>
		    </cylinder>
		  </geometry>
		</collision>
	 
		<visual name="lidar_visual">
		  <pose>0.06 0 0.15 0 0 0</pose>
		  <geometry>
		    <cylinder>
		      <radius>0.02</radius>
		      <length>0.04</length>
		    </cylinder>
		  </geometry>
		  <material>
		    <ambient>0.0 0.0 0.0 1.0</ambient>
		    <diffuse>0.0 0.0 0.0 1.0</diffuse>
		    <specular>0.0 0.0 0.0 1.0</specular>
		    <emissive>0.0 0.0 0.0 1.0</emissive>
		  </material>
		</visual>
	 
		<sensor name="lidar" type="ray">
		  <pose>0.06 0 0.18 0 0 0</pose>
		  <always_on>true</always_on>
		  <visualize>true</visualize>
		  <update_rate>5</update_rate>
		  <ray>
		    <scan>
		      <horizontal>
		        <samples>180</samples>
		        <resolution>1.00000</resolution>
		        <min_angle>0.000000</min_angle>
		        <max_angle>6.280000</max_angle>
		      </horizontal>
		    </scan>
		    <range>
		      <min>0.120000</min>
		      <max>10.0</max>
		      <resolution>0.015000</resolution>
		    </range>
		    <noise>
		      <type>gaussian</type>
		      <mean>0.0</mean>
		      <stddev>0.01</stddev>
		    </noise>
		  </ray>
		  <plugin name="scan" filename="libgazebo_ros_ray_sensor.so">
		    <ros>
		      <remapping>~/out:=scan</remapping>
		    </ros>
		    <output_type>sensor_msgs/LaserScan</output_type>
		    <frame_name>lidar_link</frame_name>
		  </plugin>
		</sensor>
	</link>

  <!-- ************************ JOINTS ***********************************  -->
  <!-- Pose of the joint is the same as the child link frame -->
  <!-- Axis is the axis of rotation relative to the child link frame -->
  
  <joint name="base_joint" type="fixed">
    <parent>base_footprint</parent>
    <child>base_link</child>
    <pose>0 0 0 0 0 0</pose>
  </joint>
  
  <joint name="mid_platform_joint" type="fixed">
    <parent>base_link</parent>
    <child>mid_platform</child>
  </joint>
  <joint name="sensor_tower" type="fixed">
    <parent>base_link</parent>
    <child>sensor_tower</child>
  </joint>
  <joint name="r_front_piller" type="fixed">
  	<parent>base_link</parent>
  	<child>right_front_lower_pillar</child>
 	</joint>
 	<joint name="l_front_piller" type="fixed">
  	<parent>base_link</parent>
  	<child>left_front_lower_pillar</child>
 	</joint>
 	
 	<joint name="r_rear_piller" type="fixed">
  	<parent>base_link</parent>
  	<child>right_rear_lower_pillar</child>
 	</joint>
 	<joint name="l_rear_piller" type="fixed">
  	<parent>base_link</parent>
  	<child>left_rear_lower_pillar</child>
 	</joint>

  <joint name="drivewhl_l_joint" type="revolute">
    <parent>base_link</parent>
    <child>drivewhl_l_link</child>
    <pose>0 0 0 0 0 0</pose>
    <axis>
      <xyz>0 0 1</xyz>
    </axis>
  </joint>

  <joint name="drivewhl_r_joint" type="revolute">
    <parent>base_link</parent>
    <child>drivewhl_r_link</child>
    <pose>0 0 0 0 0 0</pose>
    <axis>
      <xyz>0 0 1</xyz>
    </axis>
  </joint>
	
  
  <joint name='caster_joint_l' type='ball'>
    <parent>base_link</parent>
    <child>rear_caster_l</child>
  </joint>
  
  <joint name='caster_joint_r' type='ball'>
    <parent>base_link</parent>
    <child>rear_caster_r</child>
  </joint>
  
	<joint name="camera_joint" type="fixed">
    <parent>base_link</parent>
    <child>camera_link</child>
    <pose>0 0 0 0 0 0</pose>
  </joint>
  
  <joint name="lidar_joint" type="fixed">
    <parent>base_link</parent>
    <child>lidar_link</child>
    <pose>0 0 0 0 0 0</pose>
  </joint>
  
  <joint name="imu_joint" type="fixed">
    <parent>base_link</parent>
    <child>imu_link</child>
    <pose>0 0 0 0 0 0</pose>
  </joint>  

  <joint name="gps_joint" type="fixed">
    <parent>base_link</parent>
    <child>gps_link</child>
    <pose>0 0 0 0 0 0</pose>
  </joint>  

 <!-- *********************** WHEEL ODOMETRY ***************************    -->
  <plugin name="basic_mobile_bot_diff_drive" filename="libgazebo_ros_diff_drive.so">

    <update_rate>30</update_rate>

    <!-- wheels -->
    <left_joint>drivewhl_l_joint</left_joint>
    <right_joint>drivewhl_r_joint</right_joint>

    <!-- kinematics -->
    <wheel_separation>0.52</wheel_separation>
    <wheel_diameter>0.28</wheel_diameter>

    <!-- limits -->
    <max_wheel_torque>20</max_wheel_torque>
    <max_wheel_acceleration>1.0</max_wheel_acceleration>

    <!-- Receive velocity commands on this ROS topic -->
    <command_topic>cmd_vel</command_topic>

    <!-- output -->
    <!-- When false, publish no wheel odometry data to a ROS topic -->
    <publish_odom>true</publish_odom>

    <!-- When true, publish coordinate transform from odom to base_footprint -->
    <!-- I usually use the robot_localization package to publish this transform -->   
    <publish_odom_tf>false</publish_odom_tf>
    
    <!-- When true, publish coordinate transform from base_link to the wheels -->
    <!-- The robot_state_publisher package is often used to publish this transform -->   
    <publish_wheel_tf>false</publish_wheel_tf>

    <odometry_topic>odom</odometry_topic>
    <odometry_frame>odom</odometry_frame>
    <robot_base_frame>base_footprint</robot_base_frame>

    <!-- Odometry source, 0 for ENCODER, 1 for WORLD, defaults to WORLD -->
   <!-- <odometry_source>0</odometry_source> -->
		<odometry_source>1</odometry_source>
    <!-- Change the ROS topic we will publish the odometry data to -->
    <ros>
      <remapping>odom:=wheel/odometry</remapping>
    </ros>

  </plugin>

 <!-- *********************** JOINT STATE PUBLISHER *********************   -->
  
  <plugin name="basic_mobile_bot_joint_state" filename="libgazebo_ros_joint_state_publisher.so">
    <ros>
      <remapping>~/out:=joint_states</remapping>
    </ros>
    <update_rate>30</update_rate>
    <joint_name>drivewhl_l_joint</joint_name>
    <joint_name>drivewhl_r_joint</joint_name>
  </plugin>   
  
  </model>
</sdf>
